<?xml version="1.0"?>
<robot xmlns:xacro="http://www.ros.org/wiki/xacro" >

 <material name="white">
     <color rgba="1 1 1 1" />
 </material>

 <material name="orange">
     <color rgba="1 0.3 0.1 1"/>
 </material>

 <material name="blue">
     <color rgba="0.2 0.2 1 1"/>
 </material>

 <material name="black">
     <color rgba="0 0 0 1"/>
 </material>

 <material name="red">
     <color rgba="1 0 0 1"/>
 </material>

 <!-- BASE LINK -->

    <link name="base_link">

    </link>
    <joint name="chassis_joint" type="fixed">
        <parent link="base_link"/>
        <child link="chassis"/>
        <origin xyz="-0.1 0 0"/>
    </joint>

    <link name="chassis">
        <visual>
            <origin xyz="0.15 0 0.15" rpy="0 0 0"/>
            <geometry>
                <box size="0.4 0.4 0.15"/>
            </geometry>
            <material name="white"/>
        </visual>
        <collision>
            <origin xyz="0.15 0 0.15" rpy="0 0 0"/>
            <geometry>
                <box size="0.4 0.4 0.15"/>
            </geometry>
        </collision>
        <!-- ... visual and collision here ... -->
        <xacro:inertial_box mass="0.5" x="0.2" y="0.2" z="0.075">
            <origin xyz="0.15 0 0.075" rpy="0 0 0"/>
        </xacro:inertial_box>
    </link>
    <gazebo reference="chassis">
        <material>Gazebo/Black</material>
    </gazebo>

    <!-- LEFT WHEEL -->

    <joint name="left_wheel_joint" type="continuous">
        <parent link="base_link"/>
        <child link="left_wheel"/>
        <origin xyz="-0.1 0.175 0.15" rpy="-${pi/2} 0 0"/>
        <axis xyz="0 0 1"/>
    </joint>

    <link name="left_wheel">
    <visual>
        <geometry>
            <cylinder length="0.04" radius="0.05" />
        </geometry>
        <material name="blue"/>
    </visual>
    <collision>
        <origin xyz="-0.1 0.175 0.15" rpy="-${pi/2} 0 0"/>
        <geometry>
            <cylinder length="0.04" radius="0.05" />
        </geometry>
    </collision>
    <!-- ... visual and collision here ... -->
    <xacro:inertial_cylinder mass="0.1" length="0.05" radius="0.05">
        <origin xyz="0 0 0" rpy="0 0 0"/>
    </xacro:inertial_cylinder>
    </link>
    <gazebo reference="left_wheel">
        <material>Gazebo/Blue</material>
    </gazebo>
    <!-- LEFT WHEEL Front-->

    <joint name="left_wheel_joint_front" type="continuous">
        <parent link="base_link"/>
        <child link="left_wheel_front"/>
        <origin xyz="0.125 0.175 0.15" rpy="-${pi/2} 0 0"/>
        <axis xyz="0 0 1"/>
    </joint>

    <link name="left_wheel_front">
    <visual>
        <geometry>
            <cylinder length="0.04" radius="0.05" />
        </geometry>
        <material name="red"/>
    </visual>
    <collision>
        <origin xyz="0.125 0.175 0.15" rpy="-${pi/2} 0 0"/>
        <geometry>
            <cylinder length="0.04" radius="0.05" />
        </geometry>
    </collision>
    <!-- ... visual and collision here ... -->
    <xacro:inertial_cylinder mass="0.1" length="0.05" radius="0.05">
        <origin xyz="0 0 0" rpy="0 0 0"/>
    </xacro:inertial_cylinder>
    </link>
    <gazebo reference="left_wheel_front">
    <material>Gazebo/Red</material>
    </gazebo>

    <!-- RIGHT WHEEL -->

    <joint name="right_wheel_joint" type="continuous">
        <parent link="base_link"/>
        <child link="right_wheel"/>
        <origin xyz="-0.1 -0.175 0.15" rpy="${pi/2} 0 0"/>
        <axis xyz="0 0 -1"/>
    </joint>

    <link name="right_wheel">
    <visual>
        <geometry>
            <cylinder length="0.04" radius="0.05" />
        </geometry>
        <material name="orange"/>
    </visual>
    <collision>
        <origin xyz="-0.1 -0.175 0.15" rpy="${pi/2} 0 0"/>
        <geometry>
            <cylinder length="0.04" radius="0.05" />
        </geometry>
    </collision>
    <!-- ... visual and collision here ... -->
    <xacro:inertial_cylinder mass="0.1" length="0.05" radius="0.05">
        <origin xyz="0 0 0" rpy="0 0 0"/>
    </xacro:inertial_cylinder>
    </link>
    <gazebo reference="right_wheel">
        <material>Gazebo/Blue</material>
    </gazebo>
<!-- RIGHT WHEEL FRONT-->

    <joint name="right_wheel_joint_front" type="continuous">
        <parent link="base_link"/>
        <child link="right_wheel_front"/>
        <origin xyz="0.125 -0.175 0.15" rpy="${pi/2} 0 0"/>
        <axis xyz="0 0 -1"/>
    </joint>

    <link name="right_wheel_front">
    <visual>
        <geometry>
            <cylinder length="0.04" radius="0.05"/>
        </geometry>
        <material name="white"/>
    </visual>
    <collision>
        <origin xyz="0.125 -0.175 0.15" rpy="${pi/2} 0 0"/>
        <geometry>
            <cylinder length="0.04" radius="0.05" />
        </geometry>
    </collision>
    <!-- ... visual and collision here ... -->
    <xacro:inertial_cylinder mass="0.1" length="0.05" radius="0.05">
        <origin xyz="0 0 0" rpy="0 0 0"/>
    </xacro:inertial_cylinder>
    </link>
    <gazebo reference="right_wheel_front">
        <material>Gazebo/Red</material>
    </gazebo>

</robot>
